Workbook
Name abstract: 'Metrics Tags'!$A$5
Name class: 'Metrics Tags'!$A$4
Name Tag_protocol: 'Metrics Tags'!$A$2
Name Tag_status: 'Metrics Tags'!$A$3

Sheet Library
A1: group | B1: name | C1: version | D1: dependencies | E1: description
A2: com.icomm | B2: access-control | C2: 0.1.4 | E2: - Access Control 가능한 Data Object 를 위한 annotation 및 utility
A3: com.icomm | B3: spec-util | C3: 0.4.1 | E3: -JPA Specification을 이용한 Query 지원
A4: com.icomm.im | B4: data-object | C4: 0.0.1-SNAPSHOT | E4: - i-Monitor에서 사용되는 Data Object 모음
A5: com.icomm.im | B5: common | C5: 0.0.1-SNAPSHOT | D5: - com.icomm:access-control - org.springframework.boot:spring-boot-starter-security - org.springframework.boot:spring-boot-starter-webflux | E5: - Exception, Session 및 Message Helper
A6: com.icomm.im | B6: traceable | C6: 0.0.1-SNAPSHOT | D6: - com.icomm.im:data-object - org.springframework.boot:spring-boot-starter-webflux - org.springframework.boot:spring-boot-starter-aop - io.opentelemetry:opentelemetry-exporter-otlp | E6: - Opentelemetry trace 기능 사용
A7: com.icomm.im | B7: pageable-object | C7: 0.0.1-SNAPSHOT | D7: - com.icomm:access-control - com.icomm.im:common - com.icomm.im:data-object - org.springframework.boot:spring-boot-starter-security - org.springframework.boot:spring-boot-starter-aop - org.springdoc:springdoc-openapi-starter-webflux-ui | E7: - Page request를 위한 Pageable Data Object 모음 - Spring 관련 기능을 사용해야 하는 Data Object 모음 - @ComponentScan 시 "com.icomm.im.aop" 을 추가해야 한다 + ex) @SpringBootApplication(scanBasePackages = "com.icomm.im")
A8: com.icomm.im | B8: entity-base | C8: 0.0.1-SNAPSHOT | D8: - com.icomm:access-control - com.icomm:spec-util - com.icomm.im:common - com.icomm.im:pageable-object - org.springframework.boot:spring-boot-starter-security - org.springframework.boot:spring-boot-starter-validation - org.springframework.boot:spring-boot-starter-json - org.springframework.boot:spring-boot-starter-data-jpa - org.springframework.boot:spring-boot-starter-aop | E8: - @EntityLoad 지원 - IdEntity, BaseEntity 지원

Sheet Service Requirement
A1: Idx | B1: 요구사항 | C1: 대상 | D1: M/O | E1: 비고
B2: - Prometheus metric를 지원해야 한다 + path : /meter/promethus + metric name prfix : im_ | C2: 모든 서비스 | D2: 필수
B3: - Discovery Client를 지원해야 한다. + Project iM 에서 생성하는 Service는 모두 Discovery Client로 동작 (Load Balancer 제외) | C3: Project iM 서비스 | D3: 필수
B4: - Logging + docker container를 사용할 경우 /opt/im/logs 디렉토리에 log 생성 | C4: Project iM 서비스 | D4: 필수

Sheet Service List
A1: Name | B1: Type | C1: Service | D1: Repository | E1: Topic Publisher | F1: Topic Comsumer | G1: Topic Group | H1: Number | I1: Ports | J1: Description
A2: auth | B2: im | C2: Authentication & Authorization | H2: 10 | I2: 9101 | J2: - 인증 및 권한 관리
A3: gs | B3: im | C3: Global Scheduler | H3: 20 | I3: 9102 | J3: - Scheduler
A4: idx | B4: im | C4: Global Index Generator | D4: - postgresql | H4: 30 | I4: 9103 | J4: - 서비스 전체에 대해 Unique 한 Index를 생성한다(순차 증가)
A6: apl | B6: im | C6: Access Point Logger | D6: - mongodb | F6: - ApTopic | G6: - ap-logger | H6: 100 | I6: 9111 | J6: - Access Point 의 수행 결과 저장 (RequestInfo , TrapInfo)
A7: el | B7: im | C7: Event Logger | D7: - mongodb | F7: - EventTopic - AlertTopic | G7: - event-logger | H7: 110 | I7: 9112 | J7: - Event 저장
A8: al | B8: im | C8: Alert Logger | D8: - mongodb | F8: - AlertTopic | G8: - alert-manager | H8: 120 | I8: 9113 | J8: - Alert 저장
A10: ap | B10: im | C10: Access Point | D10: - redis | E10: - ApTopic | H10: 200 | I10: 9121 | J10: - 지정된 protocol 로 End Node 의 정보 수집 - End Node 에서 전송되는 Trap/Event 수신
A11: mom | B11: im | C11: Managed Object Manager | D11: - postgresql | E11: - EventTopic | F11: - ApTopic | G11: - mo-manager | H11: 210 | I11: 9122 | J11: - 관리대상 (MO) 관리 서비스 (Inventory scan, Instance management)
A12: ea | B12: im | C12: Event Analyzer | E12: - AlertTopic | F12: - EventTopic | G12: - event-alanyzer | H12: 220 | I12: 9123 | J12: - Event 분석 후 필요할 경우 Alert 발생
A13: mm | B13: im | C13: Metric Manager | F13: - EventTopic | G13: - metric-manager | H13: 230 | I13: 9124 | J13: - 통계 정보 생성 및 저장
A14: rc | B14: im | C14: Request Controller | F14: - EventTopic | G14: - request-controller | H14: 240 | I14: 9125 | J14: - 외부 요청 정보 처리
A15: ip | B15: im | C15: Information Publisher | F15: - EventTopic - AlertTopic | G15: - publisher | H15: 250 | I15: 9126 | J15: - Event & Alert 전달 (mail, SMS 등)
H17: 300 | J17: - Logger Block 을 위한 예비
H18: 400 | J18: - Core Block 을 위한 예비
A20: gw | B20: im | C20: API Gateway | H20: 500 | I20: 8080 | J20: - API Gateway
A21: lb | B21: im | C21: Load Balancer | E21: - EventTopic | H21: 510 | I21: 8761 | J21: - 부하 관리 및 Health check를 위한 eureka server
A23: kafka | B23: 3rd | C23: Message Queue | H23: 610 | I23: 9094 | J23: - Kafka Message Queue
A24: prometheus | B24: 3rd | C24: Prometheus | H24: 620 | I24: 9090 | J24: - Prometheus Server
A25: grafana | B25: 3rd | C25: Grafana | H25: 630 | I25: 3000 | J25: - Grafana Server
A26: grafana | B26: 3rd | C26: Loki | I26: 3100 | J26: - Grafana Loki
A27: promtail | B27: 3rd | C27: Promtail | H27: 640 | I27: 9080 | J27: - Grafana Promtail
A28: zipkin | B28: 3rd | C28: Zipkin | D28: - mysql | H28: 650 | I28: 9411 | J28: - Zipkin Server
A29: jaeger | B29: 3rd | C29: Jaeger | H29: 660 | I29: 16686 4317 | J29: - Jaeger Server & UI

Sheet API Mapping
A1: API Group | B1: Service Name | C1: Full Name | D1: API URL | E1: Rewrite Rule
A2: global | B2: auth | C2: =IFERROR(VLOOKUP(B2,'Service List'!A:C,3,FALSE),"") -> Authentication & Authorization | D2: /global/auth/** | E2: /global/auth/?(?<path>.*), /api/v1/$\{path}
A3: global | B3: gs | C3: =IFERROR(VLOOKUP(B3,'Service List'!A:C,3,FALSE),"") -> Global Scheduler | D3: /global/gs/** | E3: /global/gs/?(?<path>.*), /api/v1/$\{path}
A4: global | B4: idx | C4: =IFERROR(VLOOKUP(B4,'Service List'!A:C,3,FALSE),"") -> Global Index Generator | D4: /global/idx/** | E4: /global/idx/?(?<path>.*), /api/v1/$\{path}
A5: core | B5: ap | C5: =IFERROR(VLOOKUP(B5,'Service List'!A:C,3,FALSE),"") -> Access Point | D5: /core/ap/** | E5: /core/ap/?(?<path>.*), /api/v1/$\{path}
A6: core | B6: mom | C6: =IFERROR(VLOOKUP(B6,'Service List'!A:C,3,FALSE),"") -> Managed Object Manager | D6: /core/mom/** | E6: /core/mom/?(?<path>.*), /api/v1/$\{path}
A7: logger | B7: apl | C7: =IFERROR(VLOOKUP(B7,'Service List'!A:C,3,FALSE),"") -> Access Point Logger | D7: /logger/apl/** | E7: /logger/apl/?(?<path>.*), /api/v1/$\{path}
A8: logger | B8: el | C8: =IFERROR(VLOOKUP(B8,'Service List'!A:C,3,FALSE),"") -> Event Logger | D8: /logger/el/** | E8: /logger/el/?(?<path>.*), /api/v1/$\{path}
C9: =IFERROR(VLOOKUP(B9,'Service List'!A:C,3,FALSE),"")
C10: =IFERROR(VLOOKUP(B10,'Service List'!A:C,3,FALSE),"")
C11: =IFERROR(VLOOKUP(B11,'Service List'!A:C,3,FALSE),"")
C12: =IFERROR(VLOOKUP(B12,'Service List'!A:C,3,FALSE),"")
C13: =IFERROR(VLOOKUP(B13,'Service List'!A:C,3,FALSE),"")
C14: =IFERROR(VLOOKUP(B14,'Service List'!A:C,3,FALSE),"")
C15: =IFERROR(VLOOKUP(B15,'Service List'!A:C,3,FALSE),"")
C16: =IFERROR(VLOOKUP(B16,'Service List'!A:C,3,FALSE),"")
C17: =IFERROR(VLOOKUP(B17,'Service List'!A:C,3,FALSE),"")
C18: =IFERROR(VLOOKUP(B18,'Service List'!A:C,3,FALSE),"")
C19: =IFERROR(VLOOKUP(B19,'Service List'!A:C,3,FALSE),"")
C20: =IFERROR(VLOOKUP(B20,'Service List'!A:C,3,FALSE),"")
... C36: =IFERROR(VLOOKUP(B36,'Service List'!A:C,3,FALSE),"")

Sheet Network
A2: Port 사용
B3: 2377/tcp : 클러스터 관리에 사용되는 포트다.
B4: 7946/tcp, 7946/udp : 노드 간 통신에 사용된다.
B5: 4789/udp : 클러스터에서 사용되는 Ingress 오버레이 네트워크 트래픽에 사용된다.
A7: 방화벽 rule 추가
B8: $ firewall-cmd --permanent --add-rich-rule='rule family="ipv4" source address="192.168.50.0/24" accept'
B9: $ firewall-cmd --permanent --add-rich-rule='rule family="ipv4" source address="127.0.0.1" accept'
A11: docker login
B12: $ docker login nexus.i-commtech.com
A14: MacOS
B15: - Mac용 Docker Swarm 의 경우 overlay network 사용이 안됨 (https://github.com/moby/swarmkit/issues/1146#issuecomment-231412874)
A18: Node 구성
B19: Manager
C20: - 1st Manager : 192.168.50.204 (dev3) - Node 01
C21: - 2nd Manager : 192.168.50.202 (dev2) - Node 02
B22: Worker
C23: - 1st Worker : 192.168.50.201 (dev1) - Node 03
A25: master manager node 생성 (01)
B26: $ docker swarm init --advertise-addr 192.168.50.204
A28: docker stack ps 시 shutdown history 수를 1로 제한
B29: $ docker swarm update --task-history-limit 1
A31: docker swarm 용 management UI 설치
B32: $ docker run -it --rm \
B33: --name swarmpit-installer \
B34: --volume /var/run/docker.sock:/var/run/docker.sock \
B35: swarmpit/install:1.9
A38: join token 확인
B39: $ docker swarm join-token worker
B40: To add a worker to this swarm, run the following command:
B42: docker swarm join --token SWMTKN-1-01xwpzmufsygtc2qvjcik2dhet5foa3jafwnnq9mpu5vmks2ft-3gmihjjkiriza5vv5ktyhjuef 192.168.50.204:2377
B44: $ docker swarm join-token manager
B45: To add a manager to this swarm, run the following command:
B47: docker swarm join --token SWMTKN-1-01xwpzmufsygtc2qvjcik2dhet5foa3jafwnnq9mpu5vmks2ft-ayw9add46rcdxh0p5spfkgpfj 192.168.50.204:2377
A49: 2nd manager node join (dev2)
B50: - firewall 에 의해 blocking 되고 있기 때문에 port 추가 필요
B51: $ sudo firewall-cmd --add-port={2377/tcp,2377/tcp,7946/udp,4789/udp} --permanent
B52: $ sudo firewall-cmd --reload
B54: - manager node join
B55: $ docker swarm join --token SWMTKN-1-0sg2aee1v0c1mi25nqot563c4psfvimmmvyyha6rlsiae2ypw8-2nauuw8hjvgv57ki2m2y2jyya 192.168.50.204:2377
B56: This node joined a swarm as a manager.
...

Sheet Node
A1: Node ID | B1: Description | C1: Type | D1: Storage | E1: Name | F1: Swam Network
A2: 01 | B2: - dev3 개발 서버 | C2: service | D2: true | E2: dev3 | F2: - 1st Manager
A3: 02 | B3: - dev2 개발 서버 | C3: service | E3: dev2 | F3: - 2nd Manager
A4: 03 | B4: - dev1 개발 서버 | C4: service | E4: dev1 | F4: - 1st Worker
A5: 91 | B5: - Cho 개발 PC | C5: dev | E5: cho | F5: - 조규석 개발 PC

Sheet Container
A1: Container Group | B1: Service | C1: Container Name | D1: Image | E1: Dependencies | F1: Number | G1: Port | H1: Port Mapping | I1: Remark
A2: auth | B2: auth | C2: auth-db | D2: redis:latest | F2: =VLOOKUP(B2,'Service List'!$A:$J,8,FALSE) -> 10 | H2: - 10011:6379 | K2: Port export mapping rules
B3: auth | C3: auth-01 | F3: =VLOOKUP(B3,'Service List'!$A:$J,8,FALSE) -> 10 | H3: - 11011:9101 | K3: 3rd DB : 20xxx
A4: idx | B4: idx | C4: idx-db | D4: postgresql:latest | F4: =VLOOKUP(B4,'Service List'!$A:$J,8,FALSE) -> 30 | H4: - 10031:5432 | K4: 3rd Service : 21xxx
B5: idx | C5: idx-01 | E5: idx-db | F5: =VLOOKUP(B5,'Service List'!$A:$J,8,FALSE) -> 30 | G5: =VLOOKUP(B5,'Service List'!$A:$J,9,FALSE) -> 9103 | H5: - 11031:9103 | I5: - Global Indexer 01 | K5: 3rd UI : 22xxx
B6: idx | C6: idx-02 | E6: idx-db | F6: =VLOOKUP(B6,'Service List'!$A:$J,8,FALSE) -> 30 | G6: =VLOOKUP(B6,'Service List'!$A:$J,9,FALSE) -> 9103 | H6: - 11032:9103 | I6: - Global Indexer 02 | K6: iM DB : 10xxx
K7: iM Service : 11xxx
A8: apl | B8: apl | C8: apl-db | D8: postgresql:latest | F8: =VLOOKUP(B8,'Service List'!$A:$J,8,FALSE) -> 100 | H8: - 10101:5432 | K8: iM UI : 12xxx
B9: apl | C9: apl-01 | E9: apl-db | F9: =VLOOKUP(B9,'Service List'!$A:$J,8,FALSE) -> 100 | G9: =VLOOKUP(B9,'Service List'!$A:$J,9,FALSE) -> 9111 | H9: - 11101:9111 | I9: - Access Point Logger 01
A10: el | B10: el | C10: el-db | D10: postgresql:latest | F10: =VLOOKUP(B10,'Service List'!$A:$J,8,FALSE) -> 110 | H10: - 10111:5432
B11: el | C11: el-01 | E11: el-db | F11: 110 | G11: 9112 | H11: - 11111:9112
A13: ap | B13: ap | C13: ap-db | D13: redis:latest | F13: =VLOOKUP(B13,'Service List'!$A:$J,8,FALSE) -> 200 | H13: - 10201:6379
A14: mom | B14: mom | C14: mom-db | D14: postgresql:latest | F14: =VLOOKUP(B14,'Service List'!$A:$J,8,FALSE) -> 210 | H14: - 10211:5432
A16: gw | B16: gw | C16: gw-01 | F16: =VLOOKUP(B16,'Service List'!$A:$J,8,FALSE) -> 500 | G16: =VLOOKUP(B16,'Service List'!$A:$J,9,FALSE) -> 8080 | H16: - 11501:8080 | I16: - API Gateway
A17: lb | B17: lb | C17: lb-01 | F17: =VLOOKUP(B17,'Service List'!$A:$J,8,FALSE) -> 510 | G17: =VLOOKUP(B17,'Service List'!$A:$J,9,FALSE) -> 8761 | H17: - 11511:8761 | I17: - Load Balancer 01
B18: lb | C18: lb-02 | F18: =VLOOKUP(B18,'Service List'!$A:$J,8,FALSE) -> 510 | G18: =VLOOKUP(B18,'Service List'!$A:$J,9,FALSE) -> 8761 | H18: - 11512:8761 | I18: - Load Balancer 02
B19: lb | C19: lb-03 | F19: =VLOOKUP(B19,'Service List'!$A:$J,8,FALSE) -> 510 | G19: =VLOOKUP(B19,'Service List'!$A:$J,9,FALSE) -> 8761 | H19: - 11513:8761 | I19: - Load Balancer 03
A21: mq | B21: kafka | C21: kafka | D21: bitnami/kafka:4.0 | F21: =VLOOKUP(B21,'Service List'!$A:$J,8,FALSE) -> 610 | H21: - 21611:21611 | I21: - docker inside port 9092
B22: kafka | C22: kafka-ui | D22: provectuslabs/kafka-ui:latest | E22: - kafka | F22: =VLOOKUP(B22,'Service List'!$A:$J,8,FALSE) -> 610 | H22: - 22611:8080
A23: perfm | B23: prometheus | C23: prometheus | D23: prom/prometheus:v2.53.5 | F23: =VLOOKUP(B23,'Service List'!$A:$J,8,FALSE) -> 620 | H23: - 21621:9090
B24: grafana | C24: grafana | D24: grafana/grafana:12.0.2 | F24: =VLOOKUP(B24,'Service List'!$A:$J,8,FALSE) -> 630 | H24: - 21631:3000
B25: grafana | C25: loki | D25: grafana/loki:5.3 | F25: =VLOOKUP(B25,'Service List'!$A:$J,8,FALSE) -> 630 | H25: - 21632:3100 - 21633:9096 | I25: - 3100 http, 9096 grpc
A26: la | B26: promtail | C26: la-01 | D26: grafana/promtail:5.3 | F26: =VLOOKUP(B26,'Service List'!$A:$J,8,FALSE) -> 640 | H26: - 21641:9080
A27: trace | B27: jaeger | C27: trace-storage | D27: elasticsearch:9.0.2 | F27: =VLOOKUP(B27,'Service List'!$A:$J,8,FALSE) -> 660 | H27: - 20661:9200 - 20662:9300
B28: jaeger | C28: trace-server | D28: jaegertracing/all-in-one:latest | E28: - trace-storage | F28: =VLOOKUP(B28,'Service List'!$A:$J,8,FALSE) -> 660 | H28: - 21661:16686 - 21662:4317 - 21663:8888 | I28: - 4317 : gRPC - 8888 : metric management - 16686 : serve frontent

Sheet Topic
A1: Topic | B1: Publisher | C1: Consumer | D1: Description
A2: ApTopic | B2: {=IF(ISTEXT(A2),IFERROR("- " & _xlfn.TEXTJOIN(CHAR(10) & "- ", TRUE,_xlfn.CHOOSECOLS(_xlfn._xlws.FILTER('Service List'!A:J,ISNUMBER(SEARCH(Topic!A2,SUBSTITUTE('Service List'!E:E,"- ","")))),3)),""),"")} -> - Access Point | C2: {=IF(ISTEXT(A2),IFERROR("- " & _xlfn.TEXTJOIN(CHAR(10) & "- ", TRUE,_xlfn.CHOOSECOLS(_xlfn._xlws.FILTER('Service List'!A:J,ISNUMBER(SEARCH(Topic!A2,SUBSTITUTE('Service List'!F:F,"- ","")))),3)),""),"")} -> - Access Point Logger - Managed Object Manager | D2: - Access Point Notification Topic
A3: EventTopic | B3: {=IF(ISTEXT(A3),IFERROR("- " & _xlfn.TEXTJOIN(CHAR(10) & "- ", TRUE,_xlfn.CHOOSECOLS(_xlfn._xlws.FILTER('Service List'!A:J,ISNUMBER(SEARCH(Topic!A3,SUBSTITUTE('Service List'!E:E,"- ","")))),3)),""),"")} -> - Managed Object Manager - Load Balancer | C3: {=IF(ISTEXT(A3),IFERROR("- " & _xlfn.TEXTJOIN(CHAR(10) & "- ", TRUE,_xlfn.CHOOSECOLS(_xlfn._xlws.FILTER('Service List'!A:J,ISNUMBER(SEARCH(Topic!A3,SUBSTITUTE('Service List'!F:F,"- ","")))),3)),""),"")} -> - Event Logger - Event Analyzer - Metric Manager - Request Controller - Information Publisher | D3: - Event Topic
A4: NotiTopic | B4: {=IF(ISTEXT(A4),IFERROR("- " & _xlfn.TEXTJOIN(CHAR(10) & "- ", TRUE,_xlfn.CHOOSECOLS(_xlfn._xlws.FILTER('Service List'!A:J,ISNUMBER(SEARCH(Topic!A4,SUBSTITUTE('Service List'!E:E,"- ","")))),3)),""),"")} | C4: {=IF(ISTEXT(A4),IFERROR("- " & _xlfn.TEXTJOIN(CHAR(10) & "- ", TRUE,_xlfn.CHOOSECOLS(_xlfn._xlws.FILTER('Service List'!A:J,ISNUMBER(SEARCH(Topic!A4,SUBSTITUTE('Service List'!F:F,"- ","")))),3)),""),"")} | D4: - Broadcast Notification Topic + 모든 서비스에 전달하기 위한 Notification + 모든 Consumer 들은 Topic group을 가지지 않는다
B5: {=IF(ISTEXT(A5),IFERROR("- " & _xlfn.TEXTJOIN(CHAR(10) & "- ", TRUE,_xlfn.CHOOSECOLS(_xlfn._xlws.FILTER('Service List'!A:J,ISNUMBER(SEARCH(Topic!A5,SUBSTITUTE('Service List'!E:E,"- ","")))),4)),""),"")} | C5: {=IF(ISTEXT(A5),IFERROR("- " & _xlfn.TEXTJOIN(CHAR(10) & "- ", TRUE,_xlfn.CHOOSECOLS(_xlfn._xlws.FILTER('Service List'!A:J,ISNUMBER(SEARCH(Topic!A5,SUBSTITUTE('Service List'!F:F,"- ","")))),4)),""),"")}
B6: {=IF(ISTEXT(A6),IFERROR("- " & _xlfn.TEXTJOIN(CHAR(10) & "- ", TRUE,_xlfn.CHOOSECOLS(_xlfn._xlws.FILTER('Service List'!A:J,ISNUMBER(SEARCH(Topic!A6,SUBSTITUTE('Service List'!E:E,"- ","")))),4)),""),"")} | C6: {=IF(ISTEXT(A6),IFERROR("- " & _xlfn.TEXTJOIN(CHAR(10) & "- ", TRUE,_xlfn.CHOOSECOLS(_xlfn._xlws.FILTER('Service List'!A:J,ISNUMBER(SEARCH(Topic!A6,SUBSTITUTE('Service List'!F:F,"- ","")))),4)),""),"")}
B7: {=IF(ISTEXT(A7),IFERROR("- " & _xlfn.TEXTJOIN(CHAR(10) & "- ", TRUE,_xlfn.CHOOSECOLS(_xlfn._xlws.FILTER('Service List'!A:J,ISNUMBER(SEARCH(Topic!A7,SUBSTITUTE('Service List'!E:E,"- ","")))),4)),""),"")} | C7: {=IF(ISTEXT(A7),IFERROR("- " & _xlfn.TEXTJOIN(CHAR(10) & "- ", TRUE,_xlfn.CHOOSECOLS(_xlfn._xlws.FILTER('Service List'!A:J,ISNUMBER(SEARCH(Topic!A7,SUBSTITUTE('Service List'!F:F,"- ","")))),4)),""),"")}
B8: {=IF(ISTEXT(A8),IFERROR("- " & _xlfn.TEXTJOIN(CHAR(10) & "- ", TRUE,_xlfn.CHOOSECOLS(_xlfn._xlws.FILTER('Service List'!A:J,ISNUMBER(SEARCH(Topic!A8,SUBSTITUTE('Service List'!E:E,"- ","")))),4)),""),"")} | C8: {=IF(ISTEXT(A8),IFERROR("- " & _xlfn.TEXTJOIN(CHAR(10) & "- ", TRUE,_xlfn.CHOOSECOLS(_xlfn._xlws.FILTER('Service List'!A:J,ISNUMBER(SEARCH(Topic!A8,SUBSTITUTE('Service List'!F:F,"- ","")))),4)),""),"")}
B9: {=IF(ISTEXT(A9),IFERROR("- " & _xlfn.TEXTJOIN(CHAR(10) & "- ", TRUE,_xlfn.CHOOSECOLS(_xlfn._xlws.FILTER('Service List'!A:J,ISNUMBER(SEARCH(Topic!A9,SUBSTITUTE('Service List'!E:E,"- ","")))),4)),""),"")} | C9: {=IF(ISTEXT(A9),IFERROR("- " & _xlfn.TEXTJOIN(CHAR(10) & "- ", TRUE,_xlfn.CHOOSECOLS(_xlfn._xlws.FILTER('Service List'!A:J,ISNUMBER(SEARCH(Topic!A9,SUBSTITUTE('Service List'!F:F,"- ","")))),4)),""),"")}
B10: {=IF(ISTEXT(A10),IFERROR("- " & _xlfn.TEXTJOIN(CHAR(10) & "- ", TRUE,_xlfn.CHOOSECOLS(_xlfn._xlws.FILTER('Service List'!A:J,ISNUMBER(SEARCH(Topic!A10,SUBSTITUTE('Service List'!E:E,"- ","")))),4)),""),"")} | C10: {=IF(ISTEXT(A10),IFERROR("- " & _xlfn.TEXTJOIN(CHAR(10) & "- ", TRUE,_xlfn.CHOOSECOLS(_xlfn._xlws.FILTER('Service List'!A:J,ISNUMBER(SEARCH(Topic!A10,SUBSTITUTE('Service List'!F:F,"- ","")))),4)),""),"")}
B11: {=IF(ISTEXT(A11),IFERROR("- " & _xlfn.TEXTJOIN(CHAR(10) & "- ", TRUE,_xlfn.CHOOSECOLS(_xlfn._xlws.FILTER('Service List'!A:J,ISNUMBER(SEARCH(Topic!A11,SUBSTITUTE('Service List'!E:E,"- ","")))),4)),""),"")} | C11: {=IF(ISTEXT(A11),IFERROR("- " & _xlfn.TEXTJOIN(CHAR(10) & "- ", TRUE,_xlfn.CHOOSECOLS(_xlfn._xlws.FILTER('Service List'!A:J,ISNUMBER(SEARCH(Topic!A11,SUBSTITUTE('Service List'!F:F,"- ","")))),4)),""),"")}
B12: {=IF(ISTEXT(A12),IFERROR("- " & _xlfn.TEXTJOIN(CHAR(10) & "- ", TRUE,_xlfn.CHOOSECOLS(_xlfn._xlws.FILTER('Service List'!A:J,ISNUMBER(SEARCH(Topic!A12,SUBSTITUTE('Service List'!E:E,"- ","")))),4)),""),"")} | C12: {=IF(ISTEXT(A12),IFERROR("- " & _xlfn.TEXTJOIN(CHAR(10) & "- ", TRUE,_xlfn.CHOOSECOLS(_xlfn._xlws.FILTER('Service List'!A:J,ISNUMBER(SEARCH(Topic!A12,SUBSTITUTE('Service List'!F:F,"- ","")))),4)),""),"")}
B13: {=IF(ISTEXT(A13),IFERROR("- " & _xlfn.TEXTJOIN(CHAR(10) & "- ", TRUE,_xlfn.CHOOSECOLS(_xlfn._xlws.FILTER('Service List'!A:J,ISNUMBER(SEARCH(Topic!A13,SUBSTITUTE('Service List'!E:E,"- ","")))),4)),""),"")} | C13: {=IF(ISTEXT(A13),IFERROR("- " & _xlfn.TEXTJOIN(CHAR(10) & "- ", TRUE,_xlfn.CHOOSECOLS(_xlfn._xlws.FILTER('Service List'!A:J,ISNUMBER(SEARCH(Topic!A13,SUBSTITUTE('Service List'!F:F,"- ","")))),4)),""),"")}
B14: {=IF(ISTEXT(A14),IFERROR("- " & _xlfn.TEXTJOIN(CHAR(10) & "- ", TRUE,_xlfn.CHOOSECOLS(_xlfn._xlws.FILTER('Service List'!A:J,ISNUMBER(SEARCH(Topic!A14,SUBSTITUTE('Service List'!E:E,"- ","")))),4)),""),"")} | C14: {=IF(ISTEXT(A14),IFERROR("- " & _xlfn.TEXTJOIN(CHAR(10) & "- ", TRUE,_xlfn.CHOOSECOLS(_xlfn._xlws.FILTER('Service List'!A:J,ISNUMBER(SEARCH(Topic!A14,SUBSTITUTE('Service List'!F:F,"- ","")))),4)),""),"")}
B15: {=IF(ISTEXT(A15),IFERROR("- " & _xlfn.TEXTJOIN(CHAR(10) & "- ", TRUE,_xlfn.CHOOSECOLS(_xlfn._xlws.FILTER('Service List'!A:J,ISNUMBER(SEARCH(Topic!A15,SUBSTITUTE('Service List'!E:E,"- ","")))),4)),""),"")} | C15: {=IF(ISTEXT(A15),IFERROR("- " & _xlfn.TEXTJOIN(CHAR(10) & "- ", TRUE,_xlfn.CHOOSECOLS(_xlfn._xlws.FILTER('Service List'!A:J,ISNUMBER(SEARCH(Topic!A15,SUBSTITUTE('Service List'!F:F,"- ","")))),4)),""),"")}
B16: {=IF(ISTEXT(A16),IFERROR("- " & _xlfn.TEXTJOIN(CHAR(10) & "- ", TRUE,_xlfn.CHOOSECOLS(_xlfn._xlws.FILTER('Service List'!A:J,ISNUMBER(SEARCH(Topic!A16,SUBSTITUTE('Service List'!E:E,"- ","")))),4)),""),"")} | C16: {=IF(ISTEXT(A16),IFERROR("- " & _xlfn.TEXTJOIN(CHAR(10) & "- ", TRUE,_xlfn.CHOOSECOLS(_xlfn._xlws.FILTER('Service List'!A:J,ISNUMBER(SEARCH(Topic!A16,SUBSTITUTE('Service List'!F:F,"- ","")))),4)),""),"")}
... B44: {=IF(ISTEXT(A44),IFERROR("- " & _xlfn.TEXTJOIN(CHAR(10) & "- ", TRUE,_xlfn.CHOOSECOLS(_xlfn._xlws.FILTER('Service List'!A:J,ISNUMBER(SEARCH(Topic!A44,SUBSTITUTE('Service List'!E:E,"- ","")))),4)),""),"")} | C44: {=IF(ISTEXT(A44),IFERROR("- " & _xlfn.TEXTJOIN(CHAR(10) & "- ", TRUE,_xlfn.CHOOSECOLS(_xlfn._xlws.FILTER('Service List'!A:J,ISNUMBER(SEARCH(Topic!A44,SUBSTITUTE('Service List'!F:F,"- ","")))),4)),""),"")}

Sheet Event
A1: Category | B1: Type | C1: Description | D1: Publisher | E1: Condition | F1: Side-Effect
A2: Asset | B2: NewInstance | C2: - 새로운 Object instance 생성 | D2: - Managed Object Manager | E2: - 새로운 Object instance가 생성되었을 때 | F2: - Instance 신규 생성 Alert 발생
B3: DeleteInstance | C3: - 기존 Object instace 삭제 | D3: - Managed Object Manager | E3: - 기존 Object instace를 삭제했을 때 | F3: - Instance 삭제 Alert 발생
A6: ImService | B6: RegisterService | C6: - Service 등록 | D6: - Load Balancer | E6: - ImService 가 Load Balancer 에 등록될 때
B7: UnregisterService | C7: - Service 등록 해지 | D7: - Load Balancer | E7: - ImService 가 Load Balancer 에서 등록 해지될 때

Sheet Metrics
A1: Metric name | B1: Tags | G1: Service | H1: Description
A2: im.target.request | B2: protocol | C2: status | G2: - Access Point | H2: - 지정된 target에 전송되는 request package count
A3: im.target.response | B3: protocol | C3: status | G3: - Access Point | H3: - 지정된 target에서 수신되는 response package count
A4: im.receive.trap | B4: protocol | G4: - Access Point | H4: - 수신된 Trap/Event package count
A5: im.receive.message | B5: class | C5: protocol | D5: category | E5: type | G5: - Access Point Logger - Managed Object Manager - Event Logger | H5: - 수신된 모든 message count
A6: im.object.instance | B6: class | C6: abstract | G6: - Managed Object Manager | H6: - class type 의 instance 수 + abstract = true : 하위 모든 type의 instance count + abstract = false : 해당 type의 instance count

Sheet Metrics Tags
A1: Name | B1: Description | C1: Metic
A2: protocol | B2: - 사용된 Protocol Name | C2: {=SUBSTITUTE(_xlfn.REGEXREPLACE(IFERROR("-" & _xlfn.TEXTJOIN("-", TRUE,_xlfn.CHOOSECOLS(_xlfn._xlws.FILTER(Metrics!A:H,Metrics!B:B=A2),1)),"") & IFERROR("-" & _xlfn.TEXTJOIN("-", TRUE,_xlfn.CHOOSECOLS(_xlfn._xlws.FILTER(Metrics!A:H,Metrics!C:C=A2),1)),"") & IFERROR("-" & _xlfn.TEXTJOIN("-", TRUE,_xlfn.CHOOSECOLS(_xlfn._xlws.FILTER(Metrics!A:H,Metrics!D:D=A2),1)),"") & IFERROR("-" & _xlfn.TEXTJOIN("-", TRUE,_xlfn.CHOOSECOLS(_xlfn._xlws.FILTER(Metrics!A:H,Metrics!E:E=A2),1)),"") & IFERROR("-" & _xlfn.TEXTJOIN("-", TRUE,_xlfn.CHOOSECOLS(_xlfn._xlws.FILTER(Metrics!A:H,Metrics!F:F=A2),1)),""),"-",CHAR(10) & "-"),CHAR(10),"",1)} -> -im.target.request -im.target.response -im.receive.trap -im.receive.message
A3: status | B3: - Operatoin 수행 결과 + ok : 정상 + timeout : 시간 초과 + unknown : 알 수 없음 | C3: {=SUBSTITUTE(_xlfn.REGEXREPLACE(IFERROR("-" & _xlfn.TEXTJOIN("-", TRUE,_xlfn.CHOOSECOLS(_xlfn._xlws.FILTER(Metrics!A:H,Metrics!B:B=A3),1)),"") & IFERROR("-" & _xlfn.TEXTJOIN("-", TRUE,_xlfn.CHOOSECOLS(_xlfn._xlws.FILTER(Metrics!A:H,Metrics!C:C=A3),1)),"") & IFERROR("-" & _xlfn.TEXTJOIN("-", TRUE,_xlfn.CHOOSECOLS(_xlfn._xlws.FILTER(Metrics!A:H,Metrics!D:D=A3),1)),"") & IFERROR("-" & _xlfn.TEXTJOIN("-", TRUE,_xlfn.CHOOSECOLS(_xlfn._xlws.FILTER(Metrics!A:H,Metrics!E:E=A3),1)),"") & IFERROR("-" & _xlfn.TEXTJOIN("-", TRUE,_xlfn.CHOOSECOLS(_xlfn._xlws.FILTER(Metrics!A:H,Metrics!F:F=A3),1)),""),"-",CHAR(10) & "-"),CHAR(10),"",1)} -> -im.target.request -im.target.response
A4: class | B4: - Class Name (Short Name) - Object Type 정보 제공 | C4: {=SUBSTITUTE(_xlfn.REGEXREPLACE(IFERROR("-" & _xlfn.TEXTJOIN("-", TRUE,_xlfn.CHOOSECOLS(_xlfn._xlws.FILTER(Metrics!A:H,Metrics!B:B=A4),1)),"") & IFERROR("-" & _xlfn.TEXTJOIN("-", TRUE,_xlfn.CHOOSECOLS(_xlfn._xlws.FILTER(Metrics!A:H,Metrics!C:C=A4),1)),"") & IFERROR("-" & _xlfn.TEXTJOIN("-", TRUE,_xlfn.CHOOSECOLS(_xlfn._xlws.FILTER(Metrics!A:H,Metrics!D:D=A4),1)),"") & IFERROR("-" & _xlfn.TEXTJOIN("-", TRUE,_xlfn.CHOOSECOLS(_xlfn._xlws.FILTER(Metrics!A:H,Metrics!E:E=A4),1)),"") & IFERROR("-" & _xlfn.TEXTJOIN("-", TRUE,_xlfn.CHOOSECOLS(_xlfn._xlws.FILTER(Metrics!A:H,Metrics!F:F=A4),1)),""),"-",CHAR(10) & "-"),CHAR(10),"",1)} -> -im.receive.message -im.object.instance
A5: abstract | B5: - Abstract Class 여부 + true : abstract class + false : concreate class | C5: {=SUBSTITUTE(_xlfn.REGEXREPLACE(IFERROR("-" & _xlfn.TEXTJOIN("-", TRUE,_xlfn.CHOOSECOLS(_xlfn._xlws.FILTER(Metrics!A:H,Metrics!B:B=A5),1)),"") & IFERROR("-" & _xlfn.TEXTJOIN("-", TRUE,_xlfn.CHOOSECOLS(_xlfn._xlws.FILTER(Metrics!A:H,Metrics!C:C=A5),1)),"") & IFERROR("-" & _xlfn.TEXTJOIN("-", TRUE,_xlfn.CHOOSECOLS(_xlfn._xlws.FILTER(Metrics!A:H,Metrics!D:D=A5),1)),"") & IFERROR("-" & _xlfn.TEXTJOIN("-", TRUE,_xlfn.CHOOSECOLS(_xlfn._xlws.FILTER(Metrics!A:H,Metrics!E:E=A5),1)),"") & IFERROR("-" & _xlfn.TEXTJOIN("-", TRUE,_xlfn.CHOOSECOLS(_xlfn._xlws.FILTER(Metrics!A:H,Metrics!F:F=A5),1)),""),"-",CHAR(10) & "-"),CHAR(10),"",1)} -> -im.object.instance
A6: category | B6: - Data Category | C6: {=SUBSTITUTE(_xlfn.REGEXREPLACE(IFERROR("-" & _xlfn.TEXTJOIN("-", TRUE,_xlfn.CHOOSECOLS(_xlfn._xlws.FILTER(Metrics!A:H,Metrics!B:B=A6),1)),"") & IFERROR("-" & _xlfn.TEXTJOIN("-", TRUE,_xlfn.CHOOSECOLS(_xlfn._xlws.FILTER(Metrics!A:H,Metrics!C:C=A6),1)),"") & IFERROR("-" & _xlfn.TEXTJOIN("-", TRUE,_xlfn.CHOOSECOLS(_xlfn._xlws.FILTER(Metrics!A:H,Metrics!D:D=A6),1)),"") & IFERROR("-" & _xlfn.TEXTJOIN("-", TRUE,_xlfn.CHOOSECOLS(_xlfn._xlws.FILTER(Metrics!A:H,Metrics!E:E=A6),1)),"") & IFERROR("-" & _xlfn.TEXTJOIN("-", TRUE,_xlfn.CHOOSECOLS(_xlfn._xlws.FILTER(Metrics!A:H,Metrics!F:F=A6),1)),""),"-",CHAR(10) & "-"),CHAR(10),"",1)} -> -im.receive.message
A7: type | B7: - Data Type | C7: {=SUBSTITUTE(_xlfn.REGEXREPLACE(IFERROR("-" & _xlfn.TEXTJOIN("-", TRUE,_xlfn.CHOOSECOLS(_xlfn._xlws.FILTER(Metrics!A:H,Metrics!B:B=A7),1)),"") & IFERROR("-" & _xlfn.TEXTJOIN("-", TRUE,_xlfn.CHOOSECOLS(_xlfn._xlws.FILTER(Metrics!A:H,Metrics!C:C=A7),1)),"") & IFERROR("-" & _xlfn.TEXTJOIN("-", TRUE,_xlfn.CHOOSECOLS(_xlfn._xlws.FILTER(Metrics!A:H,Metrics!D:D=A7),1)),"") & IFERROR("-" & _xlfn.TEXTJOIN("-", TRUE,_xlfn.CHOOSECOLS(_xlfn._xlws.FILTER(Metrics!A:H,Metrics!E:E=A7),1)),"") & IFERROR("-" & _xlfn.TEXTJOIN("-", TRUE,_xlfn.CHOOSECOLS(_xlfn._xlws.FILTER(Metrics!A:H,Metrics!F:F=A7),1)),""),"-",CHAR(10) & "-"),CHAR(10),"",1)} -> -im.receive.message

Sheet BatchJob
A2: deployment/trace/script
B3: remove_old_data.sh
C4: - 14일이 지난 Jaeger data 삭제
A5: deployment/perfm/script
B6: delete_prometheus_data.sh
C7: 60일이 지난 prometheus data 삭제
